<?xml version='1.0' encoding='UTF-8'?>
<robot name="pybullet_reacher_robot">
  <link name="link0">
    <inertial>
      <origin xyz="0.0 0.0 0.025" rpy="0.0 -0.0 0.0"/>
      <mass value="1.0"/>
      <inertia ixx="1.0" ixy="0.0" ixz="0.0" iyy="1.0" iyz="0.0" izz="1.0"/>
    </inertial>
    <visual>
      <geometry>
        <cylinder radius="0.03" length="0.05"/>
      </geometry>
      <material name="yellow"/>
      <origin xyz="0.0 0.0 0.025" rpy="0.0 -0.0 0.0"/>
    </visual>
    <collision>
      <geometry>
        <cylinder radius="0.03" length="0.05"/>
      </geometry>
      <origin xyz="0.0 0.0 0.025" rpy="0.0 -0.0 0.0"/>
    </collision>
  </link>
  <link name="link1">
    <inertial>
      <origin xyz="0.13251996451505327 0.0 0.0" rpy="0.0 1.5707963267948966 0.0"/>
      <mass value="1.0"/>
      <inertia ixx="0.0" ixy="0.0" ixz="0.0" iyy="0.0" iyz="0.0" izz="0.0"/>
    </inertial>
    <visual>
      <geometry>
        <cylinder radius="0.015" length="0.26503992903010654"/>
      </geometry>
      <material name="blue"/>
      <origin xyz="0.13251996451505327 0.0 0.0" rpy="0.0 1.5707963267948966 0.0"/>
    </visual>
    <collision>
      <geometry>
        <cylinder radius="0.015" length="0.26503992903010654"/>
      </geometry>
      <origin xyz="0.13251996451505327 0.0 0.0" rpy="0.0 1.5707963267948966 0.0"/>
    </collision>
  </link>
  <link name="link2">
    <inertial>
      <origin xyz="0.18095562941201931 0.0 0.0" rpy="0.0 1.5707963267948966 0.0"/>
      <mass value="1.0"/>
      <inertia ixx="0.0" ixy="0.0" ixz="0.0" iyy="0.0" iyz="0.0" izz="0.0"/>
    </inertial>
    <visual>
      <geometry>
        <cylinder radius="0.015" length="0.36191125882403863"/>
      </geometry>
      <material name="sky"/>
      <origin xyz="0.18095562941201931 0.0 0.0" rpy="0.0 1.5707963267948966 0.0"/>
    </visual>
    <collision>
      <geometry>
        <cylinder radius="0.015" length="0.36191125882403863"/>
      </geometry>
      <origin xyz="0.18095562941201931 0.0 0.0" rpy="0.0 1.5707963267948966 0.0"/>
    </collision>
  </link>
  <link name="link3">
    <inertial>
      <origin xyz="0.07451472632626822 0.0 0.0" rpy="0.0 1.5707963267948966 0.0"/>
      <mass value="1.0"/>
      <inertia ixx="0.0" ixy="0.0" ixz="0.0" iyy="0.0" iyz="0.0" izz="0.0"/>
    </inertial>
    <visual>
      <geometry>
        <cylinder radius="0.015" length="0.14902945265253645"/>
      </geometry>
      <material name="green"/>
      <origin xyz="0.07451472632626822 0.0 0.0" rpy="0.0 1.5707963267948966 0.0"/>
    </visual>
    <collision>
      <geometry>
        <cylinder radius="0.015" length="0.14902945265253645"/>
      </geometry>
      <origin xyz="0.07451472632626822 0.0 0.0" rpy="0.0 1.5707963267948966 0.0"/>
    </collision>
  </link>
  <link name="link4">
    <inertial>
      <origin xyz="0.0842691746470681 0.0 0.0" rpy="0.0 1.5707963267948966 0.0"/>
      <mass value="1.0"/>
      <inertia ixx="0.0" ixy="0.0" ixz="0.0" iyy="0.0" iyz="0.0" izz="0.0"/>
    </inertial>
    <visual>
      <geometry>
        <cylinder radius="0.015" length="0.1685383492941362"/>
      </geometry>
      <material name="green"/>
      <origin xyz="0.0842691746470681 0.0 0.0" rpy="0.0 1.5707963267948966 0.0"/>
    </visual>
    <collision>
      <geometry>
        <cylinder radius="0.015" length="0.1685383492941362"/>
      </geometry>
      <origin xyz="0.0842691746470681 0.0 0.0" rpy="0.0 1.5707963267948966 0.0"/>
    </collision>
  </link>
  <link name="link5">
    <inertial>
      <origin xyz="0.15757687083927022 0.0 0.0" rpy="0.0 1.5707963267948966 0.0"/>
      <mass value="1.0"/>
      <inertia ixx="0.0" ixy="0.0" ixz="0.0" iyy="0.0" iyz="0.0" izz="0.0"/>
    </inertial>
    <visual>
      <geometry>
        <cylinder radius="0.015" length="0.31515374167854043"/>
      </geometry>
      <material name="green"/>
      <origin xyz="0.15757687083927022 0.0 0.0" rpy="0.0 1.5707963267948966 0.0"/>
    </visual>
    <collision>
      <geometry>
        <cylinder radius="0.015" length="0.31515374167854043"/>
      </geometry>
      <origin xyz="0.15757687083927022 0.0 0.0" rpy="0.0 1.5707963267948966 0.0"/>
    </collision>
  </link>
  <link name="link6">
    <inertial>
      <origin xyz="0.09370593306446279 0.0 0.0" rpy="0.0 1.5707963267948966 0.0"/>
      <mass value="1.0"/>
      <inertia ixx="0.0" ixy="0.0" ixz="0.0" iyy="0.0" iyz="0.0" izz="0.0"/>
    </inertial>
    <visual>
      <geometry>
        <cylinder radius="0.015" length="0.18741186612892557"/>
      </geometry>
      <material name="green"/>
      <origin xyz="0.09370593306446279 0.0 0.0" rpy="0.0 1.5707963267948966 0.0"/>
    </visual>
    <collision>
      <geometry>
        <cylinder radius="0.015" length="0.18741186612892557"/>
      </geometry>
      <origin xyz="0.09370593306446279 0.0 0.0" rpy="0.0 1.5707963267948966 0.0"/>
    </collision>
  </link>
  <link name="link7">
    <inertial>
      <origin xyz="0.1469663953657064 0.0 0.0" rpy="0.0 1.5707963267948966 0.0"/>
      <mass value="1.0"/>
      <inertia ixx="0.0" ixy="0.0" ixz="0.0" iyy="0.0" iyz="0.0" izz="0.0"/>
    </inertial>
    <visual>
      <geometry>
        <cylinder radius="0.015" length="0.2939327907314128"/>
      </geometry>
      <material name="green"/>
      <origin xyz="0.1469663953657064 0.0 0.0" rpy="0.0 1.5707963267948966 0.0"/>
    </visual>
    <collision>
      <geometry>
        <cylinder radius="0.015" length="0.2939327907314128"/>
      </geometry>
      <origin xyz="0.1469663953657064 0.0 0.0" rpy="0.0 1.5707963267948966 0.0"/>
    </collision>
  </link>
  <link name="link8">
    <inertial>
      <origin xyz="0.0 0.0 0.0" rpy="0.0 -0.0 0.0"/>
      <mass value="1.0"/>
      <inertia ixx="1.0" ixy="0.0" ixz="0.0" iyy="1.0" iyz="0.0" izz="1.0"/>
    </inertial>
    <visual>
      <geometry>
        <sphere radius="0.02"/>
      </geometry>
      <material name="red"/>
      <origin xyz="0.0 0.0 0.0" rpy="0.0 -0.0 0.0"/>
    </visual>
    <collision>
      <geometry>
        <sphere radius="0.02"/>
      </geometry>
      <origin xyz="0.0 0.0 0.0" rpy="0.0 -0.0 0.0"/>
    </collision>
  </link>
  <joint name="joint1" type="revolute">
    <limit effort="600.0" velocity="396.86" lower="3.14"/>
    <parent link="link0"/>
    <child link="link1"/>
    <axis xyz="0. 0. 1."/>
    <origin xyz="0.0 0.0 0.025" rpy="0.0 -0.0 0.0"/>
  </joint>
  <joint name="joint2" type="revolute">
    <limit effort="300.0" velocity="200.0" lower="-2.96705" upper="2.96705"/>
    <parent link="link1"/>
    <child link="link2"/>
    <axis xyz="0. 0. 1."/>
    <origin xyz="0.26503992903010654 0.0 0.0" rpy="0.0 -0.0 0.0"/>
  </joint>
  <joint name="joint3" type="revolute">
    <limit effort="300.0" velocity="200.0" lower="-2.96705" upper="2.96705"/>
    <parent link="link2"/>
    <child link="link3"/>
    <axis xyz="0. 0. 1."/>
    <origin xyz="0.36191125882403863 0.0 0.0" rpy="0.0 -0.0 0.0"/>
  </joint>
  <joint name="joint4" type="revolute">
    <limit effort="300.0" velocity="200.0" lower="-2.96705" upper="2.96705"/>
    <parent link="link3"/>
    <child link="link4"/>
    <axis xyz="0. 0. 1."/>
    <origin xyz="0.14902945265253645 0.0 0.0" rpy="0.0 -0.0 0.0"/>
  </joint>
  <joint name="joint5" type="revolute">
    <limit effort="300.0" velocity="200.0" lower="-2.96705" upper="2.96705"/>
    <parent link="link4"/>
    <child link="link5"/>
    <axis xyz="0. 0. 1."/>
    <origin xyz="0.1685383492941362 0.0 0.0" rpy="0.0 -0.0 0.0"/>
  </joint>
  <joint name="joint6" type="revolute">
    <limit effort="300.0" velocity="200.0" lower="-2.96705" upper="2.96705"/>
    <parent link="link5"/>
    <child link="link6"/>
    <axis xyz="0. 0. 1."/>
    <origin xyz="0.31515374167854043 0.0 0.0" rpy="0.0 -0.0 0.0"/>
  </joint>
  <joint name="joint7" type="revolute">
    <limit effort="300.0" velocity="200.0" lower="-2.96705" upper="2.96705"/>
    <parent link="link6"/>
    <child link="link7"/>
    <axis xyz="0. 0. 1."/>
    <origin xyz="0.18741186612892557 0.0 0.0" rpy="0.0 -0.0 0.0"/>
  </joint>
  <joint name="joint8" type="revolute">
    <limit effort="300.0" velocity="200.0" lower="-2.96705" upper="2.96705"/>
    <parent link="link7"/>
    <child link="link8"/>
    <axis xyz="0. 0. 1."/>
    <origin xyz="0.2939327907314128 0.0 0.0" rpy="0.0 -0.0 0.0"/>
  </joint>
  <material name="yellow">
    <color rgba="0.8 0.8 0.  1. "/>
  </material>
  <material name="blue">
    <color rgba="0.  0.  0.8 1. "/>
  </material>
  <material name="sky">
    <color rgba="0.  0.8 0.8 1. "/>
  </material>
  <material name="green">
    <color rgba="0.  0.8 0.  1. "/>
  </material>
  <material name="red">
    <color rgba="0.8 0.  0.  1. "/>
  </material>
</robot>
